[17/Apr/2018 22:27:28] "GET / HTTP/1.1" 200 1776
[17/Apr/2018 22:51:35] "GET / HTTP/1.1" 200 1776
Not Found: /favicon.ico
[17/Apr/2018 22:51:37] "GET /favicon.ico HTTP/1.1" 404 1973
[17/Apr/2018 23:15:27] "GET / HTTP/1.1" 200 1776
Not Found: /favicon.ico
[17/Apr/2018 23:15:27] "GET /favicon.ico HTTP/1.1" 404 1973
[17/Apr/2018 23:16:15] "GET / HTTP/1.1" 200 1776
[17/Apr/2018 23:16:16] "GET / HTTP/1.1" 200 1776
[17/Apr/2018 23:16:16] "GET / HTTP/1.1" 200 1776
[17/Apr/2018 23:16:16] "GET / HTTP/1.1" 200 1776
[17/Apr/2018 23:16:17] "GET / HTTP/1.1" 200 1776
[17/Apr/2018 23:17:15] "GET / HTTP/1.1" 200 1776
[17/Apr/2018 23:17:15] "GET / HTTP/1.1" 200 1776
[17/Apr/2018 23:17:15] "GET / HTTP/1.1" 200 1776
[17/Apr/2018 23:17:38] "GET / HTTP/1.1" 200 1776
[17/Apr/2018 23:17:39] "GET / HTTP/1.1" 200 1776
[17/Apr/2018 23:17:39] "GET / HTTP/1.1" 200 1776
[17/Apr/2018 23:17:46] "GET / HTTP/1.1" 200 1776
[17/Apr/2018 23:17:46] "GET / HTTP/1.1" 200 1776
[17/Apr/2018 23:17:47] "GET / HTTP/1.1" 200 1776
[17/Apr/2018 23:19:34] "GET / HTTP/1.1" 200 1776
[17/Apr/2018 23:19:36] "GET / HTTP/1.1" 200 1776
[17/Apr/2018 23:19:37] "GET / HTTP/1.1" 200 1776
[17/Apr/2018 23:19:37] "GET / HTTP/1.1" 200 1776
[17/Apr/2018 23:19:37] "GET / HTTP/1.1" 200 1776
[17/Apr/2018 23:19:37] "GET / HTTP/1.1" 200 1776
[17/Apr/2018 23:20:11] "GET / HTTP/1.1" 200 1776
[17/Apr/2018 23:20:11] "GET / HTTP/1.1" 200 1776
[17/Apr/2018 23:20:11] "GET / HTTP/1.1" 200 1776
[17/Apr/2018 23:20:11] "GET / HTTP/1.1" 200 1776
[17/Apr/2018 23:20:12] "GET / HTTP/1.1" 200 1776
[17/Apr/2018 23:20:12] "GET / HTTP/1.1" 200 1776
[17/Apr/2018 23:20:12] "GET / HTTP/1.1" 200 1776
[17/Apr/2018 23:20:12] "GET / HTTP/1.1" 200 1776
[17/Apr/2018 23:20:13] "GET / HTTP/1.1" 200 1776
[17/Apr/2018 23:41:32] "GET / HTTP/1.1" 200 1776
[17/Apr/2018 23:41:43] "GET / HTTP/1.1" 200 1776
[17/Apr/2018 23:42:06] "GET / HTTP/1.1" 200 1776
[17/Apr/2018 23:42:35] "GET / HTTP/1.1" 200 1776
[17/Apr/2018 23:43:07] "GET / HTTP/1.1" 200 1776
[17/Apr/2018 23:43:07] "GET / HTTP/1.1" 200 1776
[17/Apr/2018 23:43:45] "GET / HTTP/1.1" 200 1776
[17/Apr/2018 23:43:58] "GET / HTTP/1.1" 200 1776
[17/Apr/2018 23:43:58] "GET / HTTP/1.1" 200 1776
[18/Apr/2018 09:13:39] "GET / HTTP/1.1" 200 1776
[18/Apr/2018 12:39:54] "GET / HTTP/1.1" 200 1776
Not Found: /favicon.ico
[18/Apr/2018 12:39:54] "GET /favicon.ico HTTP/1.1" 404 1973
[19/Apr/2018 20:25:48] "GET / HTTP/1.1" 200 1776
Not Found: /favicon.ico
[19/Apr/2018 20:25:48] "GET /favicon.ico HTTP/1.1" 404 1973
[19/Apr/2018 20:26:44] "GET / HTTP/1.1" 200 1776
[19/Apr/2018 20:27:12] "GET / HTTP/1.1" 200 1776
usage: manage.py runserver [-h] [--version] [-v {0,1,2,3}]
                           [--settings SETTINGS] [--pythonpath PYTHONPATH]
                           [--traceback] [--no-color] [--ipv6] [--nothreading]
                           [--noreload] [--nostatic] [--insecure]
                           [addrport]
manage.py runserver: error: unrecognized arguments: db.sqlite3 manage.py nohup.out sepo_server testsite
usage: manage.py runserver [-h] [--version] [-v {0,1,2,3}]
                           [--settings SETTINGS] [--pythonpath PYTHONPATH]
                           [--traceback] [--no-color] [--ipv6] [--nothreading]
                           [--noreload] [--nostatic] [--insecure]
                           [addrport]
manage.py runserver: error: unrecognized arguments: db.sqlite3 manage.py nohup.out sepo_server testsite
usage: manage.py runserver [-h] [--version] [-v {0,1,2,3}]
                           [--settings SETTINGS] [--pythonpath PYTHONPATH]
                           [--traceback] [--no-color] [--ipv6] [--nothreading]
                           [--noreload] [--nostatic] [--insecure]
                           [addrport]
manage.py runserver: error: unrecognized arguments: db.sqlite3 manage.py nohup.out sepo_server testsite
Performing system checks...

System check identified no issues (0 silenced).
April 24, 2018 - 14:00:36
Django version 1.11.11, using settings 'sepo_server.settings'
Starting development server at http://0.0.0.0:8000/
Quit the server with CONTROL-C.
[24/Apr/2018 14:00:45] "GET / HTTP/1.1" 200 1776
Not Found: /favicon.ico
[24/Apr/2018 14:00:45] "GET /favicon.ico HTTP/1.1" 404 1973
[24/Apr/2018 14:00:46] "GET / HTTP/1.1" 200 1776
Performing system checks...

System check identified no issues (0 silenced).
April 24, 2018 - 14:00:43
Django version 1.11.11, using settings 'sepo_server.settings'
Starting development server at http://0.0.0.0:8000/
Quit the server with CONTROL-C.
usage: manage.py runserver [-h] [--version] [-v {0,1,2,3}]
                           [--settings SETTINGS] [--pythonpath PYTHONPATH]
                           [--traceback] [--no-color] [--ipv6] [--nothreading]
                           [--noreload] [--nostatic] [--insecure]
                           [addrport]
manage.py runserver: error: unrecognized arguments: db.sqlite3 manage.py nohup.out sepo_server testsite
usage: manage.py runserver [-h] [--version] [-v {0,1,2,3}]
                           [--settings SETTINGS] [--pythonpath PYTHONPATH]
                           [--traceback] [--no-color] [--ipv6] [--nothreading]
                           [--noreload] [--nostatic] [--insecure]
                           [addrport]
manage.py runserver: error: unrecognized arguments: db.sqlite3 manage.py nohup.out sepo_server testsite
[24/Apr/2018 14:01:47] "GET / HTTP/1.1" 200 1776
[24/Apr/2018 14:01:55] "GET /admin/ HTTP/1.1" 302 0
[24/Apr/2018 14:01:55] "GET /admin/login/?next=/admin/ HTTP/1.1" 200 1667
[24/Apr/2018 14:01:55] "GET /static/admin/css/base.css HTTP/1.1" 200 16066
[24/Apr/2018 14:01:55] "GET /static/admin/css/login.css HTTP/1.1" 200 1203
[24/Apr/2018 14:01:55] "GET /static/admin/css/fonts.css HTTP/1.1" 200 423
[24/Apr/2018 14:01:55] "GET /static/admin/fonts/Roboto-Regular-webfont.woff HTTP/1.1" 200 80304
[24/Apr/2018 14:01:55] "GET /static/admin/fonts/Roboto-Light-webfont.woff HTTP/1.1" 200 81348
[24/Apr/2018 14:02:00] "POST /admin/login/?next=/admin/ HTTP/1.1" 302 0
[24/Apr/2018 14:02:00] "GET /admin/ HTTP/1.1" 200 3753
[24/Apr/2018 14:02:01] "GET /static/admin/css/dashboard.css HTTP/1.1" 200 412
[24/Apr/2018 14:02:01] "GET /static/admin/img/icon-addlink.svg HTTP/1.1" 200 331
[24/Apr/2018 14:02:01] "GET /static/admin/img/icon-changelink.svg HTTP/1.1" 200 380
[24/Apr/2018 14:02:01] "GET /static/admin/fonts/Roboto-Bold-webfont.woff HTTP/1.1" 200 82564
[24/Apr/2018 14:02:04] "GET / HTTP/1.1" 200 1776
[24/Apr/2018 14:02:05] "GET /admin/ HTTP/1.1" 200 3753
[24/Apr/2018 14:02:08] "GET /admin/testsite/post/add/ HTTP/1.1" 200 7198
[24/Apr/2018 14:02:08] "GET /static/admin/css/forms.css HTTP/1.1" 200 8173
[24/Apr/2018 14:02:08] "GET /static/admin/js/core.js HTTP/1.1" 200 7976
[24/Apr/2018 14:02:08] "GET /static/admin/js/jquery.init.js HTTP/1.1" 200 363
[24/Apr/2018 14:02:08] "GET /static/admin/js/admin/RelatedObjectLookups.js HTTP/1.1" 200 6591
[24/Apr/2018 14:02:08] "GET /static/admin/css/widgets.css HTTP/1.1" 200 10340
[24/Apr/2018 14:02:08] "GET /admin/jsi18n/ HTTP/1.1" 200 8379
[24/Apr/2018 14:02:08] "GET /static/admin/js/actions.js HTTP/1.1" 200 6501
[24/Apr/2018 14:02:08] "GET /static/admin/js/urlify.js HTTP/1.1" 200 8186
[24/Apr/2018 14:02:08] "GET /static/admin/js/prepopulate.js HTTP/1.1" 200 1538
[24/Apr/2018 14:02:08] "GET /static/admin/js/calendar.js HTTP/1.1" 200 7790
[24/Apr/2018 14:02:08] "GET /static/admin/js/admin/DateTimeShortcuts.js HTTP/1.1" 200 20529
[24/Apr/2018 14:02:08] "GET /static/admin/js/vendor/jquery/jquery.js HTTP/1.1" 200 258648
[24/Apr/2018 14:02:08] "GET /static/admin/js/vendor/xregexp/xregexp.js HTTP/1.1" 200 128820
[24/Apr/2018 14:02:08] "GET /static/admin/js/change_form.js HTTP/1.1" 200 712
[24/Apr/2018 14:02:08] "GET /static/admin/js/prepopulate_init.js HTTP/1.1" 200 495
[24/Apr/2018 14:02:08] "GET /static/admin/img/icon-clock.svg HTTP/1.1" 200 677
[24/Apr/2018 14:02:08] "GET /static/admin/img/icon-calendar.svg HTTP/1.1" 200 1086
[24/Apr/2018 14:02:10] "GET /admin/ HTTP/1.1" 200 3753
Performing system checks...

System check identified no issues (0 silenced).
April 24, 2018 - 14:01:36
Django version 1.11.11, using settings 'sepo_server.settings'
Starting development server at http://0.0.0.0:8000/
Quit the server with CONTROL-C.
Performing system checks...

System check identified no issues (0 silenced).
April 24, 2018 - 14:06:23
Django version 1.11.11, using settings 'sepo_server.settings'
Starting development server at http://0.0.0.0:8000/
Quit the server with CONTROL-C.
Performing system checks...

System check identified no issues (0 silenced).
April 24, 2018 - 14:07:19
Django version 1.11.11, using settings 'sepo_server.settings'
Starting development server at http://0.0.0.0:8000/
Quit the server with CONTROL-C.
Performing system checks...

System check identified no issues (0 silenced).
April 24, 2018 - 14:07:31
Django version 1.11.11, using settings 'sepo_server.settings'
Starting development server at http://0.0.0.0:8000/
Quit the server with CONTROL-C.
[24/Apr/2018 14:16:11] "GET /admin/auth/group/ HTTP/1.1" 200 3392
[24/Apr/2018 14:16:11] "GET /admin/jsi18n/ HTTP/1.1" 200 8379
[24/Apr/2018 14:16:11] "GET /static/admin/css/changelists.css HTTP/1.1" 200 6170
[24/Apr/2018 14:16:11] "GET /static/admin/img/search.svg HTTP/1.1" 200 458
[24/Apr/2018 14:16:11] "GET /static/admin/img/tooltag-add.svg HTTP/1.1" 200 331
[24/Apr/2018 14:16:12] "GET /admin/ HTTP/1.1" 200 3753
[24/Apr/2018 14:16:13] "GET /admin/auth/group/add/ HTTP/1.1" 200 6246
[24/Apr/2018 14:16:13] "GET /static/admin/js/SelectBox.js HTTP/1.1" 200 5755
[24/Apr/2018 14:16:13] "GET /static/admin/js/SelectFilter2.js HTTP/1.1" 200 12389
[24/Apr/2018 14:16:13] "GET /admin/jsi18n/ HTTP/1.1" 200 8379
[24/Apr/2018 14:16:13] "GET /static/admin/img/icon-unknown.svg HTTP/1.1" 200 655
[24/Apr/2018 14:16:13] "GET /static/admin/img/selector-icons.svg HTTP/1.1" 200 3291
[24/Apr/2018 14:16:13] "GET /static/admin/img/icon-unknown-alt.svg HTTP/1.1" 200 655
[24/Apr/2018 14:16:19] "GET /admin/ HTTP/1.1" 200 3753
[24/Apr/2018 14:16:20] "GET /admin/auth/user/ HTTP/1.1" 200 6659
[24/Apr/2018 14:16:20] "GET /static/admin/img/icon-yes.svg HTTP/1.1" 200 436
[24/Apr/2018 14:16:20] "GET /admin/jsi18n/ HTTP/1.1" 200 8379
[24/Apr/2018 14:16:20] "GET /static/admin/img/sorting-icons.svg HTTP/1.1" 200 1097
[24/Apr/2018 14:16:26] "GET /admin/ HTTP/1.1" 200 3753
[24/Apr/2018 14:17:11] "GET /admin/testsite/post/ HTTP/1.1" 200 4254
[24/Apr/2018 14:17:11] "GET /admin/jsi18n/ HTTP/1.1" 200 8379
[24/Apr/2018 14:17:16] "GET /admin/testsite/post/1/change/ HTTP/1.1" 200 7442
[24/Apr/2018 14:17:16] "GET /admin/jsi18n/ HTTP/1.1" 200 8379
[24/Apr/2018 14:17:21] "GET /admin/testsite/post/1/delete/ HTTP/1.1" 200 3049
[24/Apr/2018 14:17:21] "GET /static/admin/js/cancel.js HTTP/1.1" 200 204
[24/Apr/2018 14:17:23] "POST /admin/testsite/post/1/delete/ HTTP/1.1" 302 0
[24/Apr/2018 14:17:23] "GET /admin/testsite/post/ HTTP/1.1" 200 3203
[24/Apr/2018 14:17:23] "GET /admin/jsi18n/ HTTP/1.1" 200 8379
[24/Apr/2018 14:17:26] "GET /admin/testsite/post/add/ HTTP/1.1" 200 7198
[24/Apr/2018 14:17:26] "GET /admin/jsi18n/ HTTP/1.1" 200 8379
[24/Apr/2018 14:17:28] "GET /admin/testsite/post/ HTTP/1.1" 200 3059
[24/Apr/2018 14:18:26] "GET /admin/testsite/post/add/ HTTP/1.1" 200 7198
[24/Apr/2018 14:18:26] "GET /admin/jsi18n/ HTTP/1.1" 200 8379
[24/Apr/2018 14:18:29] "GET /admin/auth/user/add/?_to_field=id&_popup=1 HTTP/1.1" 200 4594
[24/Apr/2018 14:18:29] "GET /admin/jsi18n/ HTTP/1.1" 200 8379
[24/Apr/2018 14:18:33] "GET /admin/auth/user/1/change/?_to_field=id&_popup=1 HTTP/1.1" 200 12617
[24/Apr/2018 14:18:33] "GET /admin/jsi18n/ HTTP/1.1" 200 8379
[24/Apr/2018 14:18:49] "POST /admin/auth/user/1/change/?_to_field=id&_popup=1 HTTP/1.1" 200 442
[24/Apr/2018 14:18:49] "GET /static/admin/js/popup_response.js HTTP/1.1" 200 569
[24/Apr/2018 14:19:06] "POST /admin/testsite/post/add/ HTTP/1.1" 302 0
[24/Apr/2018 14:19:06] "GET /admin/testsite/post/ HTTP/1.1" 200 4453
[24/Apr/2018 14:19:06] "GET /admin/jsi18n/ HTTP/1.1" 200 8379
[24/Apr/2018 14:19:14] "GET /admin/testsite/post/2/change/ HTTP/1.1" 200 7647
[24/Apr/2018 14:19:14] "GET /admin/jsi18n/ HTTP/1.1" 200 8379
[24/Apr/2018 14:19:17] "POST /admin/testsite/post/2/change/ HTTP/1.1" 302 0
[24/Apr/2018 14:19:17] "GET /admin/testsite/post/ HTTP/1.1" 200 4453
[24/Apr/2018 14:19:17] "GET /admin/jsi18n/ HTTP/1.1" 200 8379
[24/Apr/2018 14:19:19] "GET /admin/testsite/post/add/ HTTP/1.1" 200 7198
[24/Apr/2018 14:19:19] "GET /admin/jsi18n/ HTTP/1.1" 200 8379
[24/Apr/2018 14:19:25] "POST /admin/testsite/post/add/ HTTP/1.1" 302 0
[24/Apr/2018 14:19:25] "GET /admin/testsite/post/ HTTP/1.1" 200 4678
[24/Apr/2018 14:19:25] "GET /admin/jsi18n/ HTTP/1.1" 200 8379
[24/Apr/2018 14:33:40] "GET /admin/ HTTP/1.1" 200 5140
[24/Apr/2018 14:33:40] "GET /static/admin/img/icon-deletelink.svg HTTP/1.1" 200 392
[24/Apr/2018 14:33:43] "GET /admin/logout/ HTTP/1.1" 200 1009
[24/Apr/2018 14:33:49] "GET /admin/logout/ HTTP/1.1" 302 0
[24/Apr/2018 14:33:49] "GET /admin/ HTTP/1.1" 302 0
[24/Apr/2018 14:33:49] "GET /admin/login/?next=/admin/ HTTP/1.1" 200 1667
[24/Apr/2018 14:33:54] "GET /admin/login/?next=/admin/ HTTP/1.1" 200 1667
[24/Apr/2018 14:34:04] "GET /admin/login/?next=/admin/ HTTP/1.1" 200 1667
[24/Apr/2018 14:34:04] "GET /admin/login/?next=/admin/ HTTP/1.1" 200 1667
[24/Apr/2018 14:34:05] "GET /admin/login/?next=/admin/ HTTP/1.1" 200 1667
[24/Apr/2018 14:34:05] "GET /admin/login/?next=/admin/ HTTP/1.1" 200 1667
[24/Apr/2018 14:34:05] "GET /admin/login/?next=/admin/ HTTP/1.1" 200 1667
[24/Apr/2018 14:34:28] "GET / HTTP/1.1" 200 1776
Invalid HTTP_HOST header: 'www.baidu.com'. You may need to add u'www.baidu.com' to ALLOWED_HOSTS.
[24/Apr/2018 17:33:12] "GET http://www.baidu.com/cache/global/img/gs.gif HTTP/1.1" 400 59523
[25/Apr/2018 01:56:06] "GET / HTTP/1.1" 200 1776
Invalid HTTP_HOST header: 'www.baidu.com'. You may need to add u'www.baidu.com' to ALLOWED_HOSTS.
[25/Apr/2018 02:35:05] "GET http://www.baidu.com/cache/global/img/gs.gif HTTP/1.1" 400 59523
Invalid HTTP_HOST header: 'www.baidu.com'. You may need to add u'www.baidu.com' to ALLOWED_HOSTS.
[25/Apr/2018 11:17:49] "GET http://www.baidu.com/cache/global/img/gs.gif HTTP/1.1" 400 59523
Invalid HTTP_HOST header: 'www.baidu.com'. You may need to add u'www.baidu.com' to ALLOWED_HOSTS.
[25/Apr/2018 20:07:04] "GET http://www.baidu.com/cache/global/img/gs.gif HTTP/1.1" 400 59523
Unhandled exception in thread started by <function wrapper at 0x7f1c90c89aa0>
Performing system checks...

Traceback (most recent call last):
  File "/usr/local/lib/python2.7/dist-packages/django/utils/autoreload.py", line 228, in wrapper
    fn(*args, **kwargs)
  File "/usr/local/lib/python2.7/dist-packages/django/core/management/commands/runserver.py", line 124, in inner_run
    self.check(display_num_errors=True)
  File "/usr/local/lib/python2.7/dist-packages/django/core/management/base.py", line 359, in check
    include_deployment_checks=include_deployment_checks,
  File "/usr/local/lib/python2.7/dist-packages/django/core/management/base.py", line 346, in _run_checks
    return checks.run_checks(**kwargs)
  File "/usr/local/lib/python2.7/dist-packages/django/core/checks/registry.py", line 81, in run_checks
    new_errors = check(app_configs=app_configs)
  File "/usr/local/lib/python2.7/dist-packages/django/core/checks/urls.py", line 16, in check_url_config
    return check_resolver(resolver)
  File "/usr/local/lib/python2.7/dist-packages/django/core/checks/urls.py", line 26, in check_resolver
    return check_method()
  File "/usr/local/lib/python2.7/dist-packages/django/urls/resolvers.py", line 254, in check
    for pattern in self.url_patterns:
  File "/usr/local/lib/python2.7/dist-packages/django/utils/functional.py", line 35, in __get__
    res = instance.__dict__[self.name] = self.func(instance)
  File "/usr/local/lib/python2.7/dist-packages/django/urls/resolvers.py", line 405, in url_patterns
    patterns = getattr(self.urlconf_module, "urlpatterns", self.urlconf_module)
  File "/usr/local/lib/python2.7/dist-packages/django/utils/functional.py", line 35, in __get__
    res = instance.__dict__[self.name] = self.func(instance)
  File "/usr/local/lib/python2.7/dist-packages/django/urls/resolvers.py", line 398, in urlconf_module
    return import_module(self.urlconf_name)
  File "/usr/lib/python2.7/importlib/__init__.py", line 37, in import_module
    __import__(name)
  File "/home/team6/djangoproject/sepo_server/sepo_server/urls.py", line 21, in <module>
    url(r''. testsite.urls)
AttributeError: 'str' object has no attribute 'testsite'
Unhandled exception in thread started by <function wrapper at 0x7fbf2d23caa0>
Performing system checks...

Traceback (most recent call last):
  File "/usr/local/lib/python2.7/dist-packages/django/utils/autoreload.py", line 228, in wrapper
    fn(*args, **kwargs)
  File "/usr/local/lib/python2.7/dist-packages/django/core/management/commands/runserver.py", line 124, in inner_run
    self.check(display_num_errors=True)
  File "/usr/local/lib/python2.7/dist-packages/django/core/management/base.py", line 359, in check
    include_deployment_checks=include_deployment_checks,
  File "/usr/local/lib/python2.7/dist-packages/django/core/management/base.py", line 346, in _run_checks
    return checks.run_checks(**kwargs)
  File "/usr/local/lib/python2.7/dist-packages/django/core/checks/registry.py", line 81, in run_checks
    new_errors = check(app_configs=app_configs)
  File "/usr/local/lib/python2.7/dist-packages/django/core/checks/urls.py", line 16, in check_url_config
    return check_resolver(resolver)
  File "/usr/local/lib/python2.7/dist-packages/django/core/checks/urls.py", line 26, in check_resolver
    return check_method()
  File "/usr/local/lib/python2.7/dist-packages/django/urls/resolvers.py", line 254, in check
    for pattern in self.url_patterns:
  File "/usr/local/lib/python2.7/dist-packages/django/utils/functional.py", line 35, in __get__
    res = instance.__dict__[self.name] = self.func(instance)
  File "/usr/local/lib/python2.7/dist-packages/django/urls/resolvers.py", line 405, in url_patterns
    patterns = getattr(self.urlconf_module, "urlpatterns", self.urlconf_module)
  File "/usr/local/lib/python2.7/dist-packages/django/utils/functional.py", line 35, in __get__
    res = instance.__dict__[self.name] = self.func(instance)
  File "/usr/local/lib/python2.7/dist-packages/django/urls/resolvers.py", line 398, in urlconf_module
    return import_module(self.urlconf_name)
  File "/usr/lib/python2.7/importlib/__init__.py", line 37, in import_module
    __import__(name)
  File "/home/team6/djangoproject/sepo_server/sepo_server/urls.py", line 21, in <module>
    url(r''. testsite.urls)
AttributeError: 'str' object has no attribute 'testsite'
Unhandled exception in thread started by <function wrapper at 0x7f39de54aaa0>
Performing system checks...

Traceback (most recent call last):
  File "/usr/local/lib/python2.7/dist-packages/django/utils/autoreload.py", line 228, in wrapper
    fn(*args, **kwargs)
  File "/usr/local/lib/python2.7/dist-packages/django/core/management/commands/runserver.py", line 124, in inner_run
    self.check(display_num_errors=True)
  File "/usr/local/lib/python2.7/dist-packages/django/core/management/base.py", line 359, in check
    include_deployment_checks=include_deployment_checks,
  File "/usr/local/lib/python2.7/dist-packages/django/core/management/base.py", line 346, in _run_checks
    return checks.run_checks(**kwargs)
  File "/usr/local/lib/python2.7/dist-packages/django/core/checks/registry.py", line 81, in run_checks
    new_errors = check(app_configs=app_configs)
  File "/usr/local/lib/python2.7/dist-packages/django/core/checks/urls.py", line 16, in check_url_config
    return check_resolver(resolver)
  File "/usr/local/lib/python2.7/dist-packages/django/core/checks/urls.py", line 26, in check_resolver
    return check_method()
  File "/usr/local/lib/python2.7/dist-packages/django/urls/resolvers.py", line 254, in check
    for pattern in self.url_patterns:
  File "/usr/local/lib/python2.7/dist-packages/django/utils/functional.py", line 35, in __get__
    res = instance.__dict__[self.name] = self.func(instance)
  File "/usr/local/lib/python2.7/dist-packages/django/urls/resolvers.py", line 405, in url_patterns
    patterns = getattr(self.urlconf_module, "urlpatterns", self.urlconf_module)
  File "/usr/local/lib/python2.7/dist-packages/django/utils/functional.py", line 35, in __get__
    res = instance.__dict__[self.name] = self.func(instance)
  File "/usr/local/lib/python2.7/dist-packages/django/urls/resolvers.py", line 398, in urlconf_module
    return import_module(self.urlconf_name)
  File "/usr/lib/python2.7/importlib/__init__.py", line 37, in import_module
    __import__(name)
  File "/home/team6/djangoproject/sepo_server/sepo_server/urls.py", line 21, in <module>
    url(r'', testsite.urls)
NameError: name 'testsite' is not defined
Unhandled exception in thread started by <function wrapper at 0x7fe789b6baa0>
Performing system checks...

Traceback (most recent call last):
  File "/usr/local/lib/python2.7/dist-packages/django/utils/autoreload.py", line 228, in wrapper
    fn(*args, **kwargs)
  File "/usr/local/lib/python2.7/dist-packages/django/core/management/commands/runserver.py", line 124, in inner_run
    self.check(display_num_errors=True)
  File "/usr/local/lib/python2.7/dist-packages/django/core/management/base.py", line 359, in check
    include_deployment_checks=include_deployment_checks,
  File "/usr/local/lib/python2.7/dist-packages/django/core/management/base.py", line 346, in _run_checks
    return checks.run_checks(**kwargs)
  File "/usr/local/lib/python2.7/dist-packages/django/core/checks/registry.py", line 81, in run_checks
    new_errors = check(app_configs=app_configs)
  File "/usr/local/lib/python2.7/dist-packages/django/core/checks/urls.py", line 16, in check_url_config
    return check_resolver(resolver)
  File "/usr/local/lib/python2.7/dist-packages/django/core/checks/urls.py", line 26, in check_resolver
    return check_method()
  File "/usr/local/lib/python2.7/dist-packages/django/urls/resolvers.py", line 254, in check
    for pattern in self.url_patterns:
  File "/usr/local/lib/python2.7/dist-packages/django/utils/functional.py", line 35, in __get__
    res = instance.__dict__[self.name] = self.func(instance)
  File "/usr/local/lib/python2.7/dist-packages/django/urls/resolvers.py", line 405, in url_patterns
    patterns = getattr(self.urlconf_module, "urlpatterns", self.urlconf_module)
  File "/usr/local/lib/python2.7/dist-packages/django/utils/functional.py", line 35, in __get__
    res = instance.__dict__[self.name] = self.func(instance)
  File "/usr/local/lib/python2.7/dist-packages/django/urls/resolvers.py", line 398, in urlconf_module
    return import_module(self.urlconf_name)
  File "/usr/lib/python2.7/importlib/__init__.py", line 37, in import_module
    __import__(name)
  File "/home/team6/djangoproject/sepo_server/sepo_server/urls.py", line 21, in <module>
    url(r'', testsite.urls)
NameError: name 'testsite' is not defined
Unhandled exception in thread started by <function wrapper at 0x7feefd317aa0>
Performing system checks...

Traceback (most recent call last):
  File "/usr/local/lib/python2.7/dist-packages/django/utils/autoreload.py", line 228, in wrapper
    fn(*args, **kwargs)
  File "/usr/local/lib/python2.7/dist-packages/django/core/management/commands/runserver.py", line 124, in inner_run
    self.check(display_num_errors=True)
  File "/usr/local/lib/python2.7/dist-packages/django/core/management/base.py", line 359, in check
    include_deployment_checks=include_deployment_checks,
  File "/usr/local/lib/python2.7/dist-packages/django/core/management/base.py", line 346, in _run_checks
    return checks.run_checks(**kwargs)
  File "/usr/local/lib/python2.7/dist-packages/django/core/checks/registry.py", line 81, in run_checks
    new_errors = check(app_configs=app_configs)
  File "/usr/local/lib/python2.7/dist-packages/django/core/checks/urls.py", line 16, in check_url_config
    return check_resolver(resolver)
  File "/usr/local/lib/python2.7/dist-packages/django/core/checks/urls.py", line 26, in check_resolver
    return check_method()
  File "/usr/local/lib/python2.7/dist-packages/django/urls/resolvers.py", line 254, in check
    for pattern in self.url_patterns:
  File "/usr/local/lib/python2.7/dist-packages/django/utils/functional.py", line 35, in __get__
    res = instance.__dict__[self.name] = self.func(instance)
  File "/usr/local/lib/python2.7/dist-packages/django/urls/resolvers.py", line 405, in url_patterns
    patterns = getattr(self.urlconf_module, "urlpatterns", self.urlconf_module)
  File "/usr/local/lib/python2.7/dist-packages/django/utils/functional.py", line 35, in __get__
    res = instance.__dict__[self.name] = self.func(instance)
  File "/usr/local/lib/python2.7/dist-packages/django/urls/resolvers.py", line 398, in urlconf_module
    return import_module(self.urlconf_name)
  File "/usr/lib/python2.7/importlib/__init__.py", line 37, in import_module
    __import__(name)
  File "/home/team6/djangoproject/sepo_server/sepo_server/urls.py", line 21, in <module>
    url(r'', testsite.urls)
NameError: name 'testsite' is not defined
Unhandled exception in thread started by <function wrapper at 0x7f4cd2770aa0>
Performing system checks...

Traceback (most recent call last):
  File "/usr/local/lib/python2.7/dist-packages/django/utils/autoreload.py", line 228, in wrapper
    fn(*args, **kwargs)
  File "/usr/local/lib/python2.7/dist-packages/django/core/management/commands/runserver.py", line 124, in inner_run
    self.check(display_num_errors=True)
  File "/usr/local/lib/python2.7/dist-packages/django/core/management/base.py", line 359, in check
    include_deployment_checks=include_deployment_checks,
  File "/usr/local/lib/python2.7/dist-packages/django/core/management/base.py", line 346, in _run_checks
    return checks.run_checks(**kwargs)
  File "/usr/local/lib/python2.7/dist-packages/django/core/checks/registry.py", line 81, in run_checks
    new_errors = check(app_configs=app_configs)
  File "/usr/local/lib/python2.7/dist-packages/django/core/checks/urls.py", line 16, in check_url_config
    return check_resolver(resolver)
  File "/usr/local/lib/python2.7/dist-packages/django/core/checks/urls.py", line 26, in check_resolver
    return check_method()
  File "/usr/local/lib/python2.7/dist-packages/django/urls/resolvers.py", line 254, in check
    for pattern in self.url_patterns:
  File "/usr/local/lib/python2.7/dist-packages/django/utils/functional.py", line 35, in __get__
    res = instance.__dict__[self.name] = self.func(instance)
  File "/usr/local/lib/python2.7/dist-packages/django/urls/resolvers.py", line 405, in url_patterns
    patterns = getattr(self.urlconf_module, "urlpatterns", self.urlconf_module)
  File "/usr/local/lib/python2.7/dist-packages/django/utils/functional.py", line 35, in __get__
    res = instance.__dict__[self.name] = self.func(instance)
  File "/usr/local/lib/python2.7/dist-packages/django/urls/resolvers.py", line 398, in urlconf_module
    return import_module(self.urlconf_name)
  File "/usr/lib/python2.7/importlib/__init__.py", line 37, in import_module
    __import__(name)
  File "/home/team6/djangoproject/sepo_server/sepo_server/urls.py", line 21, in <module>
    url(r'', include(testsite.urls)),
NameError: name 'include' is not defined
Unhandled exception in thread started by <function wrapper at 0x7fe4cce0baa0>
Performing system checks...

Traceback (most recent call last):
  File "/usr/local/lib/python2.7/dist-packages/django/utils/autoreload.py", line 228, in wrapper
    fn(*args, **kwargs)
  File "/usr/local/lib/python2.7/dist-packages/django/core/management/commands/runserver.py", line 124, in inner_run
    self.check(display_num_errors=True)
  File "/usr/local/lib/python2.7/dist-packages/django/core/management/base.py", line 359, in check
    include_deployment_checks=include_deployment_checks,
  File "/usr/local/lib/python2.7/dist-packages/django/core/management/base.py", line 346, in _run_checks
    return checks.run_checks(**kwargs)
  File "/usr/local/lib/python2.7/dist-packages/django/core/checks/registry.py", line 81, in run_checks
    new_errors = check(app_configs=app_configs)
  File "/usr/local/lib/python2.7/dist-packages/django/core/checks/urls.py", line 16, in check_url_config
    return check_resolver(resolver)
  File "/usr/local/lib/python2.7/dist-packages/django/core/checks/urls.py", line 26, in check_resolver
    return check_method()
  File "/usr/local/lib/python2.7/dist-packages/django/urls/resolvers.py", line 254, in check
    for pattern in self.url_patterns:
  File "/usr/local/lib/python2.7/dist-packages/django/utils/functional.py", line 35, in __get__
    res = instance.__dict__[self.name] = self.func(instance)
  File "/usr/local/lib/python2.7/dist-packages/django/urls/resolvers.py", line 405, in url_patterns
    patterns = getattr(self.urlconf_module, "urlpatterns", self.urlconf_module)
  File "/usr/local/lib/python2.7/dist-packages/django/utils/functional.py", line 35, in __get__
    res = instance.__dict__[self.name] = self.func(instance)
  File "/usr/local/lib/python2.7/dist-packages/django/urls/resolvers.py", line 398, in urlconf_module
    return import_module(self.urlconf_name)
  File "/usr/lib/python2.7/importlib/__init__.py", line 37, in import_module
    __import__(name)
  File "/home/team6/djangoproject/sepo_server/sepo_server/urls.py", line 21, in <module>
    url(r'', include(testsite.urls)),
NameError: name 'include' is not defined
Unhandled exception in thread started by <function wrapper at 0x7fafc83efaa0>
Performing system checks...

Traceback (most recent call last):
  File "/usr/local/lib/python2.7/dist-packages/django/utils/autoreload.py", line 228, in wrapper
    fn(*args, **kwargs)
  File "/usr/local/lib/python2.7/dist-packages/django/core/management/commands/runserver.py", line 124, in inner_run
    self.check(display_num_errors=True)
  File "/usr/local/lib/python2.7/dist-packages/django/core/management/base.py", line 359, in check
    include_deployment_checks=include_deployment_checks,
  File "/usr/local/lib/python2.7/dist-packages/django/core/management/base.py", line 346, in _run_checks
    return checks.run_checks(**kwargs)
  File "/usr/local/lib/python2.7/dist-packages/django/core/checks/registry.py", line 81, in run_checks
    new_errors = check(app_configs=app_configs)
  File "/usr/local/lib/python2.7/dist-packages/django/core/checks/urls.py", line 16, in check_url_config
    return check_resolver(resolver)
  File "/usr/local/lib/python2.7/dist-packages/django/core/checks/urls.py", line 26, in check_resolver
    return check_method()
  File "/usr/local/lib/python2.7/dist-packages/django/urls/resolvers.py", line 254, in check
    for pattern in self.url_patterns:
  File "/usr/local/lib/python2.7/dist-packages/django/utils/functional.py", line 35, in __get__
    res = instance.__dict__[self.name] = self.func(instance)
  File "/usr/local/lib/python2.7/dist-packages/django/urls/resolvers.py", line 405, in url_patterns
    patterns = getattr(self.urlconf_module, "urlpatterns", self.urlconf_module)
  File "/usr/local/lib/python2.7/dist-packages/django/utils/functional.py", line 35, in __get__
    res = instance.__dict__[self.name] = self.func(instance)
  File "/usr/local/lib/python2.7/dist-packages/django/urls/resolvers.py", line 398, in urlconf_module
    return import_module(self.urlconf_name)
  File "/usr/lib/python2.7/importlib/__init__.py", line 37, in import_module
    __import__(name)
  File "/home/team6/djangoproject/sepo_server/sepo_server/urls.py", line 21, in <module>
    url(r'', include(testsite.urls)),
NameError: name 'include' is not defined
Unhandled exception in thread started by <function wrapper at 0x7f0496d13aa0>
Performing system checks...

Traceback (most recent call last):
  File "/usr/local/lib/python2.7/dist-packages/django/utils/autoreload.py", line 228, in wrapper
    fn(*args, **kwargs)
  File "/usr/local/lib/python2.7/dist-packages/django/core/management/commands/runserver.py", line 124, in inner_run
    self.check(display_num_errors=True)
  File "/usr/local/lib/python2.7/dist-packages/django/core/management/base.py", line 359, in check
    include_deployment_checks=include_deployment_checks,
  File "/usr/local/lib/python2.7/dist-packages/django/core/management/base.py", line 346, in _run_checks
    return checks.run_checks(**kwargs)
  File "/usr/local/lib/python2.7/dist-packages/django/core/checks/registry.py", line 81, in run_checks
    new_errors = check(app_configs=app_configs)
  File "/usr/local/lib/python2.7/dist-packages/django/core/checks/urls.py", line 16, in check_url_config
    return check_resolver(resolver)
  File "/usr/local/lib/python2.7/dist-packages/django/core/checks/urls.py", line 26, in check_resolver
    return check_method()
  File "/usr/local/lib/python2.7/dist-packages/django/urls/resolvers.py", line 254, in check
    for pattern in self.url_patterns:
  File "/usr/local/lib/python2.7/dist-packages/django/utils/functional.py", line 35, in __get__
    res = instance.__dict__[self.name] = self.func(instance)
  File "/usr/local/lib/python2.7/dist-packages/django/urls/resolvers.py", line 405, in url_patterns
    patterns = getattr(self.urlconf_module, "urlpatterns", self.urlconf_module)
  File "/usr/local/lib/python2.7/dist-packages/django/utils/functional.py", line 35, in __get__
    res = instance.__dict__[self.name] = self.func(instance)
  File "/usr/local/lib/python2.7/dist-packages/django/urls/resolvers.py", line 398, in urlconf_module
    return import_module(self.urlconf_name)
  File "/usr/lib/python2.7/importlib/__init__.py", line 37, in import_module
    __import__(name)
  File "/home/team6/djangoproject/sepo_server/sepo_server/urls.py", line 21, in <module>
    url(r'', include(testsite.urls)),
NameError: name 'include' is not defined
Unhandled exception in thread started by <function wrapper at 0x7f8d5c728aa0>
Performing system checks...

Traceback (most recent call last):
  File "/usr/local/lib/python2.7/dist-packages/django/utils/autoreload.py", line 228, in wrapper
    fn(*args, **kwargs)
  File "/usr/local/lib/python2.7/dist-packages/django/core/management/commands/runserver.py", line 124, in inner_run
    self.check(display_num_errors=True)
  File "/usr/local/lib/python2.7/dist-packages/django/core/management/base.py", line 359, in check
    include_deployment_checks=include_deployment_checks,
  File "/usr/local/lib/python2.7/dist-packages/django/core/management/base.py", line 346, in _run_checks
    return checks.run_checks(**kwargs)
  File "/usr/local/lib/python2.7/dist-packages/django/core/checks/registry.py", line 81, in run_checks
    new_errors = check(app_configs=app_configs)
  File "/usr/local/lib/python2.7/dist-packages/django/core/checks/urls.py", line 16, in check_url_config
    return check_resolver(resolver)
  File "/usr/local/lib/python2.7/dist-packages/django/core/checks/urls.py", line 26, in check_resolver
    return check_method()
  File "/usr/local/lib/python2.7/dist-packages/django/urls/resolvers.py", line 254, in check
    for pattern in self.url_patterns:
  File "/usr/local/lib/python2.7/dist-packages/django/utils/functional.py", line 35, in __get__
    res = instance.__dict__[self.name] = self.func(instance)
  File "/usr/local/lib/python2.7/dist-packages/django/urls/resolvers.py", line 405, in url_patterns
    patterns = getattr(self.urlconf_module, "urlpatterns", self.urlconf_module)
  File "/usr/local/lib/python2.7/dist-packages/django/utils/functional.py", line 35, in __get__
    res = instance.__dict__[self.name] = self.func(instance)
  File "/usr/local/lib/python2.7/dist-packages/django/urls/resolvers.py", line 398, in urlconf_module
    return import_module(self.urlconf_name)
  File "/usr/lib/python2.7/importlib/__init__.py", line 37, in import_module
    __import__(name)
  File "/home/team6/djangoproject/sepo_server/sepo_server/urls.py", line 21, in <module>
    url(r'', include(testsite.urls)),
NameError: name 'include' is not defined
Unhandled exception in thread started by <function wrapper at 0x7ff08a7f8aa0>
Performing system checks...

Traceback (most recent call last):
  File "/usr/local/lib/python2.7/dist-packages/django/utils/autoreload.py", line 228, in wrapper
    fn(*args, **kwargs)
  File "/usr/local/lib/python2.7/dist-packages/django/core/management/commands/runserver.py", line 124, in inner_run
    self.check(display_num_errors=True)
  File "/usr/local/lib/python2.7/dist-packages/django/core/management/base.py", line 359, in check
    include_deployment_checks=include_deployment_checks,
  File "/usr/local/lib/python2.7/dist-packages/django/core/management/base.py", line 346, in _run_checks
    return checks.run_checks(**kwargs)
  File "/usr/local/lib/python2.7/dist-packages/django/core/checks/registry.py", line 81, in run_checks
    new_errors = check(app_configs=app_configs)
  File "/usr/local/lib/python2.7/dist-packages/django/core/checks/urls.py", line 16, in check_url_config
    return check_resolver(resolver)
  File "/usr/local/lib/python2.7/dist-packages/django/core/checks/urls.py", line 26, in check_resolver
    return check_method()
  File "/usr/local/lib/python2.7/dist-packages/django/urls/resolvers.py", line 254, in check
    for pattern in self.url_patterns:
  File "/usr/local/lib/python2.7/dist-packages/django/utils/functional.py", line 35, in __get__
    res = instance.__dict__[self.name] = self.func(instance)
  File "/usr/local/lib/python2.7/dist-packages/django/urls/resolvers.py", line 405, in url_patterns
    patterns = getattr(self.urlconf_module, "urlpatterns", self.urlconf_module)
  File "/usr/local/lib/python2.7/dist-packages/django/utils/functional.py", line 35, in __get__
    res = instance.__dict__[self.name] = self.func(instance)
  File "/usr/local/lib/python2.7/dist-packages/django/urls/resolvers.py", line 398, in urlconf_module
    return import_module(self.urlconf_name)
  File "/usr/lib/python2.7/importlib/__init__.py", line 37, in import_module
    __import__(name)
  File "/home/team6/djangoproject/sepo_server/sepo_server/urls.py", line 21, in <module>
    url(r'', include(testsite.urls)),
NameError: name 'testsite' is not defined
Unhandled exception in thread started by <function wrapper at 0x7f2aa5082aa0>
Performing system checks...

Traceback (most recent call last):
  File "/usr/local/lib/python2.7/dist-packages/django/utils/autoreload.py", line 228, in wrapper
    fn(*args, **kwargs)
  File "/usr/local/lib/python2.7/dist-packages/django/core/management/commands/runserver.py", line 124, in inner_run
    self.check(display_num_errors=True)
  File "/usr/local/lib/python2.7/dist-packages/django/core/management/base.py", line 359, in check
    include_deployment_checks=include_deployment_checks,
  File "/usr/local/lib/python2.7/dist-packages/django/core/management/base.py", line 346, in _run_checks
    return checks.run_checks(**kwargs)
  File "/usr/local/lib/python2.7/dist-packages/django/core/checks/registry.py", line 81, in run_checks
    new_errors = check(app_configs=app_configs)
  File "/usr/local/lib/python2.7/dist-packages/django/core/checks/urls.py", line 16, in check_url_config
    return check_resolver(resolver)
  File "/usr/local/lib/python2.7/dist-packages/django/core/checks/urls.py", line 26, in check_resolver
    return check_method()
  File "/usr/local/lib/python2.7/dist-packages/django/urls/resolvers.py", line 254, in check
    for pattern in self.url_patterns:
  File "/usr/local/lib/python2.7/dist-packages/django/utils/functional.py", line 35, in __get__
    res = instance.__dict__[self.name] = self.func(instance)
  File "/usr/local/lib/python2.7/dist-packages/django/urls/resolvers.py", line 405, in url_patterns
    patterns = getattr(self.urlconf_module, "urlpatterns", self.urlconf_module)
  File "/usr/local/lib/python2.7/dist-packages/django/utils/functional.py", line 35, in __get__
    res = instance.__dict__[self.name] = self.func(instance)
  File "/usr/local/lib/python2.7/dist-packages/django/urls/resolvers.py", line 398, in urlconf_module
    return import_module(self.urlconf_name)
  File "/usr/lib/python2.7/importlib/__init__.py", line 37, in import_module
    __import__(name)
  File "/home/team6/djangoproject/sepo_server/sepo_server/urls.py", line 21, in <module>
    url(r'', include(testsite.urls)),
NameError: name 'testsite' is not defined
Unhandled exception in thread started by <function wrapper at 0x7f9044fb2aa0>
Performing system checks...

Traceback (most recent call last):
  File "/usr/local/lib/python2.7/dist-packages/django/utils/autoreload.py", line 228, in wrapper
    fn(*args, **kwargs)
  File "/usr/local/lib/python2.7/dist-packages/django/core/management/commands/runserver.py", line 124, in inner_run
    self.check(display_num_errors=True)
  File "/usr/local/lib/python2.7/dist-packages/django/core/management/base.py", line 359, in check
    include_deployment_checks=include_deployment_checks,
  File "/usr/local/lib/python2.7/dist-packages/django/core/management/base.py", line 346, in _run_checks
Unhandled exception in thread started by <function wrapper at 0x7f8f877e6aa0>
    return checks.run_checks(**kwargs)
Performing system checks...

Traceback (most recent call last):
  File "/usr/local/lib/python2.7/dist-packages/django/utils/autoreload.py", line 228, in wrapper
  File "/usr/local/lib/python2.7/dist-packages/django/core/checks/registry.py", line 81, in run_checks
    new_errors = check(app_configs=app_configs)
      File "/usr/local/lib/python2.7/dist-packages/django/core/checks/urls.py", line 16, in check_url_config
fn(*args, **kwargs)
  File "/usr/local/lib/python2.7/dist-packages/django/core/management/commands/runserver.py", line 124, in inner_run
    return check_resolver(resolver)
  File "/usr/local/lib/python2.7/dist-packages/django/core/checks/urls.py", line 26, in check_resolver
        return check_method()
self.check(display_num_errors=True)
  File "/usr/local/lib/python2.7/dist-packages/django/urls/resolvers.py", line 254, in check
  File "/usr/local/lib/python2.7/dist-packages/django/core/management/base.py", line 359, in check
    for pattern in self.url_patterns:
  File "/usr/local/lib/python2.7/dist-packages/django/utils/functional.py", line 35, in __get__
        include_deployment_checks=include_deployment_checks,
res = instance.__dict__[self.name] = self.func(instance)
  File "/usr/local/lib/python2.7/dist-packages/django/urls/resolvers.py", line 405, in url_patterns
  File "/usr/local/lib/python2.7/dist-packages/django/core/management/base.py", line 346, in _run_checks
    return checks.run_checks(**kwargs)
      File "/usr/local/lib/python2.7/dist-packages/django/core/checks/registry.py", line 81, in run_checks
patterns = getattr(self.urlconf_module, "urlpatterns", self.urlconf_module)
  File "/usr/local/lib/python2.7/dist-packages/django/utils/functional.py", line 35, in __get__
    new_errors = check(app_configs=app_configs)
    res = instance.__dict__[self.name] = self.func(instance)
  File "/usr/local/lib/python2.7/dist-packages/django/core/checks/urls.py", line 16, in check_url_config
  File "/usr/local/lib/python2.7/dist-packages/django/urls/resolvers.py", line 398, in urlconf_module
    return check_resolver(resolver)
  File "/usr/local/lib/python2.7/dist-packages/django/core/checks/urls.py", line 26, in check_resolver
        return check_method()
  File "/usr/local/lib/python2.7/dist-packages/django/urls/resolvers.py", line 254, in check
return import_module(self.urlconf_name)
  File "/usr/lib/python2.7/importlib/__init__.py", line 37, in import_module
    __import__(name)
      File "/home/team6/djangoproject/sepo_server/sepo_server/urls.py", line 21, in <module>
for pattern in self.url_patterns:
  File "/usr/local/lib/python2.7/dist-packages/django/utils/functional.py", line 35, in __get__
        url(r'', include(testsite.urls)),
res = instance.__dict__[self.name] = self.func(instance)
NameError  File "/usr/local/lib/python2.7/dist-packages/django/urls/resolvers.py", line 405, in url_patterns
: name 'testsite' is not defined
    patterns = getattr(self.urlconf_module, "urlpatterns", self.urlconf_module)
  File "/usr/local/lib/python2.7/dist-packages/django/utils/functional.py", line 35, in __get__
    res = instance.__dict__[self.name] = self.func(instance)
  File "/usr/local/lib/python2.7/dist-packages/django/urls/resolvers.py", line 398, in urlconf_module
    return import_module(self.urlconf_name)
  File "/usr/lib/python2.7/importlib/__init__.py", line 37, in import_module
    __import__(name)
  File "/home/team6/djangoproject/sepo_server/sepo_server/urls.py", line 21, in <module>
    url(r'', include(testsite.urls)),
NameError: name 'testsite' is not defined
Unhandled exception in thread started by <function wrapper at 0x7fd8ede52aa0>
Performing system checks...

Traceback (most recent call last):
  File "/usr/local/lib/python2.7/dist-packages/django/utils/autoreload.py", line 228, in wrapper
    fn(*args, **kwargs)
  File "/usr/local/lib/python2.7/dist-packages/django/core/management/commands/runserver.py", line 124, in inner_run
    self.check(display_num_errors=True)
  File "/usr/local/lib/python2.7/dist-packages/django/core/management/base.py", line 359, in check
    include_deployment_checks=include_deployment_checks,
  File "/usr/local/lib/python2.7/dist-packages/django/core/management/base.py", line 346, in _run_checks
    return checks.run_checks(**kwargs)
  File "/usr/local/lib/python2.7/dist-packages/django/core/checks/registry.py", line 81, in run_checks
    new_errors = check(app_configs=app_configs)
  File "/usr/local/lib/python2.7/dist-packages/django/core/checks/urls.py", line 16, in check_url_config
    return check_resolver(resolver)
  File "/usr/local/lib/python2.7/dist-packages/django/core/checks/urls.py", line 26, in check_resolver
    return check_method()
  File "/usr/local/lib/python2.7/dist-packages/django/urls/resolvers.py", line 254, in check
    for pattern in self.url_patterns:
  File "/usr/local/lib/python2.7/dist-packages/django/utils/functional.py", line 35, in __get__
    res = instance.__dict__[self.name] = self.func(instance)
  File "/usr/local/lib/python2.7/dist-packages/django/urls/resolvers.py", line 405, in url_patterns
    patterns = getattr(self.urlconf_module, "urlpatterns", self.urlconf_module)
  File "/usr/local/lib/python2.7/dist-packages/django/utils/functional.py", line 35, in __get__
    res = instance.__dict__[self.name] = self.func(instance)
  File "/usr/local/lib/python2.7/dist-packages/django/urls/resolvers.py", line 398, in urlconf_module
    return import_module(self.urlconf_name)
  File "/usr/lib/python2.7/importlib/__init__.py", line 37, in import_module
    __import__(name)
  File "/home/team6/djangoproject/sepo_server/sepo_server/urls.py", line 21, in <module>
    url(r'', include(testsite.urls)),
NameError: name 'testsite' is not defined
Unhandled exception in thread started by <function wrapper at 0x7fa9c154faa0>
Performing system checks...

Traceback (most recent call last):
  File "/usr/local/lib/python2.7/dist-packages/django/utils/autoreload.py", line 228, in wrapper
    fn(*args, **kwargs)
  File "/usr/local/lib/python2.7/dist-packages/django/core/management/commands/runserver.py", line 124, in inner_run
    self.check(display_num_errors=True)
  File "/usr/local/lib/python2.7/dist-packages/django/core/management/base.py", line 359, in check
    include_deployment_checks=include_deployment_checks,
  File "/usr/local/lib/python2.7/dist-packages/django/core/management/base.py", line 346, in _run_checks
    return checks.run_checks(**kwargs)
  File "/usr/local/lib/python2.7/dist-packages/django/core/checks/registry.py", line 81, in run_checks
    new_errors = check(app_configs=app_configs)
  File "/usr/local/lib/python2.7/dist-packages/django/core/checks/urls.py", line 16, in check_url_config
    return check_resolver(resolver)
  File "/usr/local/lib/python2.7/dist-packages/django/core/checks/urls.py", line 26, in check_resolver
    return check_method()
  File "/usr/local/lib/python2.7/dist-packages/django/urls/resolvers.py", line 254, in check
    for pattern in self.url_patterns:
  File "/usr/local/lib/python2.7/dist-packages/django/utils/functional.py", line 35, in __get__
    res = instance.__dict__[self.name] = self.func(instance)
  File "/usr/local/lib/python2.7/dist-packages/django/urls/resolvers.py", line 405, in url_patterns
    patterns = getattr(self.urlconf_module, "urlpatterns", self.urlconf_module)
  File "/usr/local/lib/python2.7/dist-packages/django/utils/functional.py", line 35, in __get__
    res = instance.__dict__[self.name] = self.func(instance)
  File "/usr/local/lib/python2.7/dist-packages/django/urls/resolvers.py", line 398, in urlconf_module
    return import_module(self.urlconf_name)
  File "/usr/lib/python2.7/importlib/__init__.py", line 37, in import_module
    __import__(name)
  File "/home/team6/djangoproject/sepo_server/sepo_server/urls.py", line 21, in <module>
    url(r'', include(testsite.urls)),
NameError: name 'testsite' is not defined
Error: That port is already in use.
Error: That port is already in use.
Error: That port is already in use.
Error: That port is already in use.
Performing system checks...

System check identified no issues (0 silenced).
April 29, 2018 - 21:37:49
Django version 1.11.11, using settings 'sepo_server.settings'
Starting development server at http://0.0.0.0:8000/
Quit the server with CONTROL-C.
Unhandled exception in thread started by <function wrapper at 0x7f8337d1caa0>
Performing system checks...

Traceback (most recent call last):
  File "/usr/local/lib/python2.7/dist-packages/django/utils/autoreload.py", line 228, in wrapper
    fn(*args, **kwargs)
  File "/usr/local/lib/python2.7/dist-packages/django/core/management/commands/runserver.py", line 124, in inner_run
    self.check(display_num_errors=True)
  File "/usr/local/lib/python2.7/dist-packages/django/core/management/base.py", line 359, in check
    include_deployment_checks=include_deployment_checks,
  File "/usr/local/lib/python2.7/dist-packages/django/core/management/base.py", line 346, in _run_checks
    return checks.run_checks(**kwargs)
  File "/usr/local/lib/python2.7/dist-packages/django/core/checks/registry.py", line 81, in run_checks
    new_errors = check(app_configs=app_configs)
  File "/usr/local/lib/python2.7/dist-packages/django/core/checks/urls.py", line 16, in check_url_config
    return check_resolver(resolver)
  File "/usr/local/lib/python2.7/dist-packages/django/core/checks/urls.py", line 26, in check_resolver
    return check_method()
  File "/usr/local/lib/python2.7/dist-packages/django/urls/resolvers.py", line 254, in check
    for pattern in self.url_patterns:
  File "/usr/local/lib/python2.7/dist-packages/django/utils/functional.py", line 35, in __get__
    res = instance.__dict__[self.name] = self.func(instance)
  File "/usr/local/lib/python2.7/dist-packages/django/urls/resolvers.py", line 405, in url_patterns
    patterns = getattr(self.urlconf_module, "urlpatterns", self.urlconf_module)
  File "/usr/local/lib/python2.7/dist-packages/django/utils/functional.py", line 35, in __get__
    res = instance.__dict__[self.name] = self.func(instance)
  File "/usr/local/lib/python2.7/dist-packages/django/urls/resolvers.py", line 398, in urlconf_module
    return import_module(self.urlconf_name)
  File "/usr/lib/python2.7/importlib/__init__.py", line 37, in import_module
    __import__(name)
  File "/home/team6/djangoproject/sepo_server/sepo_server/urls.py", line 21, in <module>
    url(r'', include('testsite.urls')),
  File "/usr/local/lib/python2.7/dist-packages/django/conf/urls/__init__.py", line 50, in include
    urlconf_module = import_module(urlconf_module)
  File "/usr/lib/python2.7/importlib/__init__.py", line 37, in import_module
    __import__(name)
  File "/home/team6/djangoproject/sepo_server/testsite/urls.py", line 5, in <module>
    url(r'^$',views.post_list, name='post_list'),
AttributeError: 'module' object has no attribute 'post_list'
Unhandled exception in thread started by <function wrapper at 0x7f4899f96aa0>
Performing system checks...

Traceback (most recent call last):
  File "/usr/local/lib/python2.7/dist-packages/django/utils/autoreload.py", line 228, in wrapper
    fn(*args, **kwargs)
  File "/usr/local/lib/python2.7/dist-packages/django/core/management/commands/runserver.py", line 124, in inner_run
    self.check(display_num_errors=True)
  File "/usr/local/lib/python2.7/dist-packages/django/core/management/base.py", line 359, in check
    include_deployment_checks=include_deployment_checks,
  File "/usr/local/lib/python2.7/dist-packages/django/core/management/base.py", line 346, in _run_checks
    return checks.run_checks(**kwargs)
  File "/usr/local/lib/python2.7/dist-packages/django/core/checks/registry.py", line 81, in run_checks
    new_errors = check(app_configs=app_configs)
  File "/usr/local/lib/python2.7/dist-packages/django/core/checks/urls.py", line 16, in check_url_config
    return check_resolver(resolver)
  File "/usr/local/lib/python2.7/dist-packages/django/core/checks/urls.py", line 26, in check_resolver
    return check_method()
  File "/usr/local/lib/python2.7/dist-packages/django/urls/resolvers.py", line 254, in check
    for pattern in self.url_patterns:
  File "/usr/local/lib/python2.7/dist-packages/django/utils/functional.py", line 35, in __get__
    res = instance.__dict__[self.name] = self.func(instance)
  File "/usr/local/lib/python2.7/dist-packages/django/urls/resolvers.py", line 405, in url_patterns
    patterns = getattr(self.urlconf_module, "urlpatterns", self.urlconf_module)
  File "/usr/local/lib/python2.7/dist-packages/django/utils/functional.py", line 35, in __get__
    res = instance.__dict__[self.name] = self.func(instance)
  File "/usr/local/lib/python2.7/dist-packages/django/urls/resolvers.py", line 398, in urlconf_module
    return import_module(self.urlconf_name)
  File "/usr/lib/python2.7/importlib/__init__.py", line 37, in import_module
    __import__(name)
  File "/home/team6/djangoproject/sepo_server/sepo_server/urls.py", line 21, in <module>
    url(r'', include('testsite.urls')),
  File "/usr/local/lib/python2.7/dist-packages/django/conf/urls/__init__.py", line 50, in include
    urlconf_module = import_module(urlconf_module)
  File "/usr/lib/python2.7/importlib/__init__.py", line 37, in import_module
    __import__(name)
  File "/home/team6/djangoproject/sepo_server/testsite/urls.py", line 5, in <module>
    url(r'^$',views.post_list, name='post_list'),
AttributeError: 'module' object has no attribute 'post_list'
[29/Apr/2018 22:48:05] "GET / HTTP/1.1" 200 0
Not Found: /favicon.ico
[29/Apr/2018 22:48:05] "GET /favicon.ico HTTP/1.1" 404 2140
[29/Apr/2018 22:52:13] "GET / HTTP/1.1" 200 138
Invalid HTTP_HOST header: 'www.baidu.com'. You may need to add u'www.baidu.com' to ALLOWED_HOSTS.
[29/Apr/2018 22:52:47] "GET http://www.baidu.com/cache/global/img/gs.gif HTTP/1.1" 400 59773
[29/Apr/2018 22:57:19] "GET / HTTP/1.1" 200 735
[29/Apr/2018 23:01:53] "GET / HTTP/1.1" 200 735
[29/Apr/2018 23:01:58] "GET / HTTP/1.1" 200 735
[29/Apr/2018 23:02:47] "GET / HTTP/1.1" 200 735
[29/Apr/2018 23:06:45] "GET / HTTP/1.1" 200 735
[29/Apr/2018 23:06:50] "GET / HTTP/1.1" 200 735
[29/Apr/2018 23:06:52] "GET / HTTP/1.1" 200 735
[29/Apr/2018 23:06:54] "GET / HTTP/1.1" 200 735
[29/Apr/2018 23:09:46] "GET / HTTP/1.1" 200 735
[29/Apr/2018 23:09:47] "GET / HTTP/1.1" 200 735
[29/Apr/2018 23:09:47] "GET / HTTP/1.1" 200 735
[29/Apr/2018 23:09:47] "GET / HTTP/1.1" 200 735
[29/Apr/2018 23:09:48] "GET / HTTP/1.1" 200 735
[29/Apr/2018 23:09:48] "GET / HTTP/1.1" 200 735
[29/Apr/2018 23:09:48] "GET / HTTP/1.1" 200 735
[29/Apr/2018 23:09:49] "GET / HTTP/1.1" 200 735
[29/Apr/2018 23:09:49] "GET / HTTP/1.1" 200 735
[29/Apr/2018 23:09:50] "GET / HTTP/1.1" 200 735
[29/Apr/2018 23:09:51] "GET / HTTP/1.1" 200 735
[29/Apr/2018 23:09:52] "GET / HTTP/1.1" 200 735
[29/Apr/2018 23:09:52] "GET / HTTP/1.1" 200 735
[29/Apr/2018 23:09:52] "GET / HTTP/1.1" 200 735
[29/Apr/2018 23:55:46] "GET / HTTP/1.1" 200 735
[30/Apr/2018 00:07:55] "GET / HTTP/1.1" 200 735
[30/Apr/2018 01:19:06] "GET / HTTP/1.1" 200 735
[30/Apr/2018 01:19:06] "GET / HTTP/1.1" 200 735
[30/Apr/2018 01:19:06] "GET / HTTP/1.1" 200 735
Invalid HTTP_HOST header: u'oop.postech.ac.kr:8000'. You may need to add u'oop.postech.ac.kr' to ALLOWED_HOSTS.
[30/Apr/2018 05:01:01] "GET / HTTP/1.0" 400 58990
Invalid HTTP_HOST header: 'www.baidu.com'. You may need to add u'www.baidu.com' to ALLOWED_HOSTS.
[30/Apr/2018 07:42:40] "GET http://www.baidu.com/cache/global/img/gs.gif HTTP/1.1" 400 59773
Invalid HTTP_HOST header: 'www.baidu.com'. You may need to add u'www.baidu.com' to ALLOWED_HOSTS.
[30/Apr/2018 16:28:10] "GET http://www.baidu.com/cache/global/img/gs.gif HTTP/1.1" 400 59773
